Traceback (most recent call last):
  File "/Users/mmccull/opt/anaconda3/lib/python3.8/site-packages/jupyter_cache/executors/utils.py", line 51, in single_nb_execution
    executenb(
  File "/Users/mmccull/opt/anaconda3/lib/python3.8/site-packages/nbclient/client.py", line 1112, in execute
    return NotebookClient(nb=nb, resources=resources, km=km, **kwargs).execute()
  File "/Users/mmccull/opt/anaconda3/lib/python3.8/site-packages/nbclient/util.py", line 74, in wrapped
    return just_run(coro(*args, **kwargs))
  File "/Users/mmccull/opt/anaconda3/lib/python3.8/site-packages/nbclient/util.py", line 53, in just_run
    return loop.run_until_complete(coro)
  File "/Users/mmccull/opt/anaconda3/lib/python3.8/asyncio/base_events.py", line 616, in run_until_complete
    return future.result()
  File "/Users/mmccull/opt/anaconda3/lib/python3.8/site-packages/nbclient/client.py", line 553, in async_execute
    await self.async_execute_cell(
  File "/Users/mmccull/opt/anaconda3/lib/python3.8/site-packages/nbclient/client.py", line 857, in async_execute_cell
    self._check_raise_for_error(cell, exec_reply)
  File "/Users/mmccull/opt/anaconda3/lib/python3.8/site-packages/nbclient/client.py", line 760, in _check_raise_for_error
    raise CellExecutionError.from_cell_and_msg(cell, exec_reply_content)
nbclient.exceptions.CellExecutionError: An error occurred while executing the following cell:
------------------
from tabulate import tabulate
s0 = np.array([1,2,5,10,20.0])
# Generate a data set
def mm_from_params(S0,vmax,Km):  
    return vmax*S0/(Km + S0)
vmax = 7.5
Km = 4.0
truth = mm_from_params(s0,vmax,Km)
n_trials = 5
data = np.empty((truth.shape[0],n_trials))
s0_total = np.empty((s0.shape[0],n_trials))
for i in range(n_trials):
    # estimate error based on normal distribution 99.9% data within 7.5%
    error = np.random.normal(0,0.03,truth.shape[0])
    # estimate error from uniform distribution with maximum value of 5%
    #error = 0.1*(np.random.rand(truth.shape[0])-0.5)
    # generate data by adding error to truth
    data[:,i] = truth*(1+error)
    # keep flattened s0 array
    s0_total[:,i] = s0
combined_data = np.column_stack((s0,data))
print(tabulate(combined_data,headers=["[S]0","Trial 1", "Trial 2", "Trial 3", "Trial 4", "Trial 5"]))
------------------

[0;31m---------------------------------------------------------------------------[0m
[0;31mModuleNotFoundError[0m                       Traceback (most recent call last)
[0;32m<ipython-input-10-e7a272c13a12>[0m in [0;36m<module>[0;34m[0m
[0;32m----> 1[0;31m [0;32mfrom[0m [0mtabulate[0m [0;32mimport[0m [0mtabulate[0m[0;34m[0m[0;34m[0m[0m
[0m[1;32m      2[0m [0ms0[0m [0;34m=[0m [0mnp[0m[0;34m.[0m[0marray[0m[0;34m([0m[0;34m[[0m[0;36m1[0m[0;34m,[0m[0;36m2[0m[0;34m,[0m[0;36m5[0m[0;34m,[0m[0;36m10[0m[0;34m,[0m[0;36m20.0[0m[0;34m][0m[0;34m)[0m[0;34m[0m[0;34m[0m[0m
[1;32m      3[0m [0;31m# Generate a data set[0m[0;34m[0m[0;34m[0m[0;34m[0m[0m
[1;32m      4[0m [0;32mdef[0m [0mmm_from_params[0m[0;34m([0m[0mS0[0m[0;34m,[0m[0mvmax[0m[0;34m,[0m[0mKm[0m[0;34m)[0m[0;34m:[0m[0;34m[0m[0;34m[0m[0m
[1;32m      5[0m     [0;32mreturn[0m [0mvmax[0m[0;34m*[0m[0mS0[0m[0;34m/[0m[0;34m([0m[0mKm[0m [0;34m+[0m [0mS0[0m[0;34m)[0m[0;34m[0m[0;34m[0m[0m

[0;31mModuleNotFoundError[0m: No module named 'tabulate'
ModuleNotFoundError: No module named 'tabulate'

