Traceback (most recent call last):
  File "/Users/mmccull/opt/anaconda3/lib/python3.8/site-packages/jupyter_cache/executors/utils.py", line 51, in single_nb_execution
    executenb(
  File "/Users/mmccull/opt/anaconda3/lib/python3.8/site-packages/nbclient/client.py", line 1112, in execute
    return NotebookClient(nb=nb, resources=resources, km=km, **kwargs).execute()
  File "/Users/mmccull/opt/anaconda3/lib/python3.8/site-packages/nbclient/util.py", line 74, in wrapped
    return just_run(coro(*args, **kwargs))
  File "/Users/mmccull/opt/anaconda3/lib/python3.8/site-packages/nbclient/util.py", line 53, in just_run
    return loop.run_until_complete(coro)
  File "/Users/mmccull/opt/anaconda3/lib/python3.8/asyncio/base_events.py", line 616, in run_until_complete
    return future.result()
  File "/Users/mmccull/opt/anaconda3/lib/python3.8/site-packages/nbclient/client.py", line 553, in async_execute
    await self.async_execute_cell(
  File "/Users/mmccull/opt/anaconda3/lib/python3.8/site-packages/nbclient/client.py", line 857, in async_execute_cell
    self._check_raise_for_error(cell, exec_reply)
  File "/Users/mmccull/opt/anaconda3/lib/python3.8/site-packages/nbclient/client.py", line 760, in _check_raise_for_error
    raise CellExecutionError.from_cell_and_msg(cell, exec_reply_content)
nbclient.exceptions.CellExecutionError: An error occurred while executing the following cell:
------------------
# plot data
import numpy as np
import matplotlib.pyplot as plt
%matplotlib inline
# setup plot parameters
fontsize=16
fig = plt.figure(figsize=(8,8), dpi= 80, facecolor='w', edgecolor='k')
ax = plt.subplot(111)
ax.grid(b=True, which='major', axis='both', color='#808080', linestyle='--')
ax.set_ylabel("$v_0$ ($\mu$M/s)",size=fontsize)
ax.set_xlabel("$[S]_0$ (mM)",size=fontsize)
plt.tick_params(axis='both',labelsize=fontsize)
ax.plot(s0,v0,'o',lw=2)
s = np.arange(np.amin(s0),np.amax(s0),0.01)
ax.plot(s,mm(res_lsq.x,s),lw=3,label="fit")
plt.legend(fontsize=fontsize)
------------------

[0;31m---------------------------------------------------------------------------[0m
[0;31mNameError[0m                                 Traceback (most recent call last)
[0;32m<ipython-input-5-a3369de19bfc>[0m in [0;36m<module>[0;34m[0m
[1;32m     13[0m [0max[0m[0;34m.[0m[0mplot[0m[0;34m([0m[0ms0[0m[0;34m,[0m[0mv0[0m[0;34m,[0m[0;34m'o'[0m[0;34m,[0m[0mlw[0m[0;34m=[0m[0;36m2[0m[0;34m)[0m[0;34m[0m[0;34m[0m[0m
[1;32m     14[0m [0ms[0m [0;34m=[0m [0mnp[0m[0;34m.[0m[0marange[0m[0;34m([0m[0mnp[0m[0;34m.[0m[0mamin[0m[0;34m([0m[0ms0[0m[0;34m)[0m[0;34m,[0m[0mnp[0m[0;34m.[0m[0mamax[0m[0;34m([0m[0ms0[0m[0;34m)[0m[0;34m,[0m[0;36m0.01[0m[0;34m)[0m[0;34m[0m[0;34m[0m[0m
[0;32m---> 15[0;31m [0max[0m[0;34m.[0m[0mplot[0m[0;34m([0m[0ms[0m[0;34m,[0m[0mmm[0m[0;34m([0m[0mres_lsq[0m[0;34m.[0m[0mx[0m[0;34m,[0m[0ms[0m[0;34m)[0m[0;34m,[0m[0mlw[0m[0;34m=[0m[0;36m3[0m[0;34m,[0m[0mlabel[0m[0;34m=[0m[0;34m"fit"[0m[0;34m)[0m[0;34m[0m[0;34m[0m[0m
[0m[1;32m     16[0m [0mplt[0m[0;34m.[0m[0mlegend[0m[0;34m([0m[0mfontsize[0m[0;34m=[0m[0mfontsize[0m[0;34m)[0m[0;34m[0m[0;34m[0m[0m

[0;31mNameError[0m: name 'res_lsq' is not defined
NameError: name 'res_lsq' is not defined

